Workbook

Sheet 사용안내
B2: AI 애플리케이션 개발자 과정 — 단위 프로젝트 산출물 관리
B3: AI캠퍼스 | 교과목별 팀 배정 · 제출 현황 관리 워크북
B6: ■ 이 파일 구성
B7: ① 사용안내 | C7: 지금 이 시트입니다. 시트 구성과 사용 방법, 상태 값의 의미를 안내합니다.
B8: ② 프로젝트 안내 | C8: 4개 교과목의 프로젝트 주제·세부 수행내용·주요 산출물·평가 기준 전체를 정리했습니다. 참여자 안내용으로 사용하세요.
B9: ③ 제출현황 | C9: 실제 관리 시트입니다. 교과목별로 팀을 따로 배정하고, 팀×산출물의 제출 링크·상태·검토 결과를 기록합니다.
B10: ④ 대시보드 | C10: 제출현황을 자동 집계합니다. 교과목별 팀×산출물 제출 상태와 완료율을 한눈에 확인합니다. (직접 입력 금지)
B12: ■ 교과목별 팀 배정
B13: 핵심 | C13: 교과목이 끝날 때마다 팀이 바뀔 수 있으므로, 팀은 교과목 단위로 따로 배정합니다.
B14: 구조 | C14: [제출현황]은 교과목1 / 교과목2 / 교과목3 / 교과목4 네 구역으로 나뉘고, 각 구역마다 팀명을 독립적으로 입력합니다.
B15: 예 | C15: 교과목1의 A팀과 교과목2의 A팀은 서로 다른 구성이어도 됩니다. 구역마다 팀명을 새로 적으면 됩니다.
B17: ■ 사용 순서
B18: 1단계 | C18: [제출현황]에서 교과목별로 노란색 '팀명' 칸에 그 교과목의 팀 이름을 입력합니다. (교과목마다 팀 3~8개, 쓰는 팀만 채우면 됩니다)
B19: 2단계 | C19: 참여자(팀)가 각 산출물의 '제출 링크' 칸에 GitHub·구글드라이브·노션 등 URL을 붙여넣고 '제출 상태'를 '제출완료'로 바꿉니다.
B20: 3단계 | C20: 운영자는 링크 확인 후 '검토 상태'(승인/반려/검토중)와 '운영자 피드백'을 기록합니다.
B21: 4단계 | C21: [대시보드]에서 교과목별·팀별 진행률을 확인합니다.
B23: ■ 상태 값 안내
B24: 제출 상태 | C24: 미제출 · 제출완료 · 재제출 (참여자가 선택)
B25: 검토 상태 | C25: 미검토 · 검토중 · 승인 · 반려 (운영자가 선택)
B27: ■ 참고
B28: 입력 칸 | C28: 노란색 칸만 직접 입력합니다. 대시보드의 수식 칸은 자동 계산되니 수정하지 마세요.
B29: 팀명 규칙 | C29: 한 교과목 구역 안에서는 팀명이 겹치지 않게 입력하세요. 사용하지 않는 팀은 팀명을 비워두면 대시보드에서 자동 제외됩니다.
B30: 예시팀 | C30: 교과목1의 맨 위 '예시팀' 블록은 작성 예시입니다. 실제 사용 시 팀명을 덮어쓰거나 내용을 지우세요.

Sheet 프로젝트 안내
A1: 교과목 | B1: 프로젝트 주제 | C1: 세부 수행내용 | D1: 산출물 코드 | E1: 주요 산출물 | F1: 관련 평가 기준
A2: 교과목 1 웹 서비스 기초 및 AI 백엔드 개발 | B2: 실시간 로그 대시보드 인터페이스 | C2: 1. 백엔드·DB·UI 통합 아키텍처 구현 및 배포 실습 2. 실시간 데이터 스트리밍을 통한 로그 시각화 대시보드 최종 제작 3. 사용자 피드백 데이터를 반영한 AI 답변 품질 고도화 및 서비스 최적화 | D2: P1-1 | E2: API 설계 문서 | F2: 1. 엔드포인트 URL이 리소스 중심으로 일관되게 명명되고, HTTP Method(GET/POST/PUT/DELETE)가 의미에 맞게 사용되었는가? 2. 표준화된 에러 응답 포맷(HTTP Status Code+에러 코드+메시지+상세)이 정의되고, 4xx/5xx 예외 처리 규칙이 문서화되었는가? 3. Request/Response Pydantic 모델이 필수/선택 필드·타입 힌트·예시값(example)을 명확히 정의하고, 중첩 JSON은 nested 모델로 표현되는가?
D3: P1-2 | E3: 화면 설계서 | F3: 1. 모든 화면(메인·상세·입력·설정·에러)의 와이어프레임이 누락 없이 작성되고, 정보 계층구조(IA)가 논리적인가? 2. 컴포넌트(버튼·입력폼·테이블·차트)의 스타일·색상·폰트·여백이 전체 화면에서 통일된 디자인 시스템을 따르는가? 3. 클릭·호버·드래그·스크롤·필터·새로고침 등 모든 사용자 액션에 대한 시스템 반응이 정의되었는가?
D4: P1-3 | E4: 데이터베이스 설계서 | F4: 1. 테이블이 3정규화(3NF) 기준으로 설계되어 데이터 중복이 최소화되고, 이상현상(삽입/갱신/삭제)이 방지되었는가? 2. 논리 ERD(엔티티·속성·관계·카디널리티)와 물리 ERD(테이블·컬럼·PK/FK·인덱스)가 모두 작성되고 일치하는가? 3. 모든 컬럼의 데이터 타입·길이·제약조건·기본값·코멘트가 명확히 정의되었는가?
D5: P1-4 | E5: 대시보드 구현 결과물 | F5: 1. 구현된 대시보드가 배포 환경에서 동작하며, 핵심 기능(로그 수집·조회·시각화)이 시연 가능한가?
A6: 교과목 2 단일 에이전트 추론 및 AI 오케스트레이션 | B6: 복합 API 연계 일정 조정 에이전트 | C6: 1. LangGraph를 이용한 다중 도구(Multi-tool) 선택 및 순환형 워크플로우 설계 2. 에이전트의 판단 오류를 스스로 수정하는 자가 성찰 및 피드백 루프 구현 3. 실시간 API 데이터 기반의 의사결정 시나리오 테스트 및 서비스 배포 실습 | D6: P2-1 | E6: 에이전트 아키텍처 설계서 | F6: 1. StateGraph의 각 Node(Start·Tools·Decision·End 등)가 에이전트의 사고 흐름(인지→판단→행동→검증)에 맞게 논리적으로 배치되었는가? 2. 분기 조건이 명확한 기준값/정책으로 정의되고, 예외 흐름(Fallback)도 엣지로 표현되었는가? 3. 단기·장기 기억 연동, 컨텍스트 윈도우 관리, 요약(Summarization) 전략이 그래프 설계에 반영되었는가? 4. Function Calling·Tool Use 호출 흐름이 시퀀스/상태 흐름도로 명확히 표현되었는가? 5. 상태 객체 필드(messages·tools_called·error_count 등)가 타입 힌트와 함께 정의되고 불필요한 중복이 없는가?
D7: P2-2 | E7: 에이전트 시험 결과 보고서 | F7: 1. 판단 오류(할루시네이션·도구 선택 오류·파라미터 누락·응답 불일치 등) 감지 기준(룰/휴리스틱/LLM)이 구체적으로 정의되었는가? 2. 오류 유형별 재시도·대체 전략(Fallback)·휴리스틱 업데이트 이력이 버전별로 문서화되고, 개선 전후 성능 비교가 포함되었는가? 3. 오류 감지→원인 분석→수정 전략 선택→재실행→검증 피드백 루프가 순서도(Activity Diagram)로 표현되었는가? 4. 자기 성찰 전후 태스크 완료율·도구 선택 정확도·응답 일관성·평균 재시행 횟수가 수치로 제시되었는가?
A8: 교과목 3 멀티 에이전트 협업 및 서비스 운영 | B8: 에러 자가 치유(Auto Healing) 워크플로우 | C8: 1. 에이전트 협업 시나리오 및 구조 설계 2. 장애 유형별 복구 로직 및 자동화 파이프라인 구현 3. 협업 기반 실행 흐름 통합 구현 4. 서비스 배포 및 결과 검증 | D8: P3-1 | E8: 멀티 에이전트 아키텍처 설계서 | F8: 1. 아키텍처 구조가 비즈니스 요구사항(응답 속도·결정 일관성·장애 격리)에 맞게 선택되고 근거가 문서화되었는가? 2. 각 에이전트의 역할(Planner·Executor·Critic·Memory Keeper 등)·책임 범위·의존 관계가 정의되고 중복/공백이 없는가? 3. 에이전트 간 작업 전달(Handoff) 시 컨텍스트(상태·메모리·중간 결과)가 누락 없이 전달되는 구조가 설계되었는가?
D9: P3-2 | E9: 배포 및 장애 복구 보고서 | F9: 1. 멀티 컨테이너(Pod/Service) 배포 매니페스트가 작성되고, 서비스 디스커버리·로드밸런싱·시크릿 관리가 포함되었는가? 2. 네트워크·DB·API·LLM·프롬프트 등 유형별 감지 메트릭이 수립되었는가? 3. 장애 유형별 자동 복구 스크립트(재시작·재연결·대체 모델·캐시 폴백)가 구현되고, 수동 개입 없이 복구되는 시나리오 비율이 제시되었는가?
D10: P3-3 | E10: 파이프라인 구현 결과 보고서 | F10: 1. 커밋→빌드→테스트(단위/통합)→배포 전체 단계가 파이프라인 다이어그램으로 표현되고, 각 단계 입출력·실패 시 처리가 정의되었는가? 2. 파이프라인 내 테스트 커버리지 기준·테스트 데이터 관리·실패 시 블로킹 정책이 명시되었는가? 3. 실행 결과(성공/실패/지연)가 Slack/Teams/PagerDuty로 자동 알림되고, 장애 시 담당자 할당·에스컬레이션이 설정되었는가?
A11: 교과목 4 노코드 멀티 에이전트 워크플로우 설계 및 운영 | B11: 노코드·로코드 기반 기업형 지능형 기술 지원 자동화(Tech Support) 워크플로우 | C11: 1. 노코드·로코드 기반 RAG 및 도구 노드 구현 2. 멀티 에이전트 오케스트레이션 구현 3. 운영 안정화 및 예외 처리(Error Handling) 4. 서비스 테스트 및 결과 검증 | D11: P4-1 | E11: 노코드 워크플로우 설계서 | F11: 1. Trigger→처리→출력 전체 흐름이 비즈니스 로직(지능형 기술 지원)에 맞게 연결되고, 병렬/분기/루프 구조가 적절히 사용되었는가? 2. 외부 서비스(Slack/Email/Jira/Notion/Database/API) 연동 노드가 인증(OAuth/API Key)과 에러 처리를 포함해 안정적으로 구성되었는가? 3. 노드 간 페이로드 스키마·변환 로직(Mapper/Formatter)·필수/선택 필드·예시가 연결선(Edge)별로 문서화되었는가?
D12: P4-2 | E12: RAG 아키텍처 설계서 | F12: 1. 원본 문서 특성에 맞는 청킹 단위·오버랩(Overlap)·청크 길이 분포가 최적화되고 근거가 제시되었는가? 2. 임베딩 모델 선정 이유(성능·다국어·도메인·비용)·벡터 차원·거리 계산 방식(Cosine/Euclidean)이 명시되었는가? 3. 컬렉션/인덱스 명명 규칙·파티션/샤딩 전략·메타데이터 구조·백업/복구·확장성(Scaling) 방안이 설계되었는가?
D13: P4-3 | E13: 워크플로우 실행 결과서 | F13: 1. 주요 시나리오에 대한 실행 테스트 로그와 예외 상황 처리 동작 결과가 포함되어 있는가?

Sheet 제출현황
A1: 팀명 | B1: 교과목 | C1: 산출물 코드 | D1: 주요 산출물 | E1: 제출 링크 | F1: 제출 상태 | G1: 제출일 | H1: 검토 상태 | I1: 운영자 피드백 | J1: _key
A2: ■ 교과목 1 | 웹 서비스 기초 및 AI 백엔드 개발 — AI 서비스 로그 분석 및 운영 대시보드 구축
A3: 예시팀명 (팀원 이름) | B3: 교과목 1 | C3: P1-1 | D3: API 설계 문서 | E3: https://github.com/example-team/p1-1-api | F3: 제출완료 | G3: 2026-09-07 | H3: 승인 | I3: API 명세 확인 완료 | J3: =A3&"|"&C3 -> 예시팀명 (팀원 이름)|P1-1
B4: 교과목 1 | C4: P1-2 | D4: 화면 설계서 | E4: https://github.com/example-team/p1-2-ui | F4: 제출완료 | G4: 2026-09-08 | H4: 검토중 | I4: 화면 설계 검토 중 | J4: =A3&"|"&C4 -> 예시팀명 (팀원 이름)|P1-2
B5: 교과목 1 | C5: P1-3 | D5: 데이터베이스 설계서 | F5: 미제출 | H5: 미검토 | J5: =A3&"|"&C5 -> 예시팀명 (팀원 이름)|P1-3
B6: 교과목 1 | C6: P1-4 | D6: 대시보드 구현 결과물 | F6: 미제출 | H6: 미검토 | J6: =A3&"|"&C6 -> 예시팀명 (팀원 이름)|P1-4
B7: 교과목 1 | C7: P1-1 | D7: API 설계 문서 | F7: 미제출 | H7: 미검토 | J7: =A7&"|"&C7 -> |P1-1
B8: 교과목 1 | C8: P1-2 | D8: 화면 설계서 | F8: 미제출 | H8: 미검토 | J8: =A7&"|"&C8 -> |P1-2
B9: 교과목 1 | C9: P1-3 | D9: 데이터베이스 설계서 | F9: 미제출 | H9: 미검토 | J9: =A7&"|"&C9 -> |P1-3
B10: 교과목 1 | C10: P1-4 | D10: 대시보드 구현 결과물 | F10: 미제출 | H10: 미검토 | J10: =A7&"|"&C10 -> |P1-4
B11: 교과목 1 | C11: P1-1 | D11: API 설계 문서 | F11: 미제출 | H11: 미검토 | J11: =A11&"|"&C11 -> |P1-1
B12: 교과목 1 | C12: P1-2 | D12: 화면 설계서 | F12: 미제출 | H12: 미검토 | J12: =A11&"|"&C12 -> |P1-2
B13: 교과목 1 | C13: P1-3 | D13: 데이터베이스 설계서 | F13: 미제출 | H13: 미검토 | J13: =A11&"|"&C13 -> |P1-3
B14: 교과목 1 | C14: P1-4 | D14: 대시보드 구현 결과물 | F14: 미제출 | H14: 미검토 | J14: =A11&"|"&C14 -> |P1-4
B15: 교과목 1 | C15: P1-1 | D15: API 설계 문서 | F15: 미제출 | H15: 미검토 | J15: =A15&"|"&C15 -> |P1-1
B16: 교과목 1 | C16: P1-2 | D16: 화면 설계서 | F16: 미제출 | H16: 미검토 | J16: =A15&"|"&C16 -> |P1-2
B17: 교과목 1 | C17: P1-3 | D17: 데이터베이스 설계서 | F17: 미제출 | H17: 미검토 | J17: =A15&"|"&C17 -> |P1-3
B18: 교과목 1 | C18: P1-4 | D18: 대시보드 구현 결과물 | F18: 미제출 | H18: 미검토 | J18: =A15&"|"&C18 -> |P1-4
B19: 교과목 1 | C19: P1-1 | D19: API 설계 문서 | F19: 미제출 | H19: 미검토 | J19: =A19&"|"&C19 -> |P1-1
B20: 교과목 1 | C20: P1-2 | D20: 화면 설계서 | F20: 미제출 | H20: 미검토 | J20: =A19&"|"&C20 -> |P1-2
B21: 교과목 1 | C21: P1-3 | D21: 데이터베이스 설계서 | F21: 미제출 | H21: 미검토 | J21: =A19&"|"&C21 -> |P1-3
B22: 교과목 1 | C22: P1-4 | D22: 대시보드 구현 결과물 | F22: 미제출 | H22: 미검토 | J22: =A19&"|"&C22 -> |P1-4
B23: 교과목 1 | C23: P1-1 | D23: API 설계 문서 | F23: 미제출 | H23: 미검토 | J23: =A23&"|"&C23 -> |P1-1
B24: 교과목 1 | C24: P1-2 | D24: 화면 설계서 | F24: 미제출 | H24: 미검토 | J24: =A23&"|"&C24 -> |P1-2
B25: 교과목 1 | C25: P1-3 | D25: 데이터베이스 설계서 | F25: 미제출 | H25: 미검토 | J25: =A23&"|"&C25 -> |P1-3
B26: 교과목 1 | C26: P1-4 | D26: 대시보드 구현 결과물 | F26: 미제출 | H26: 미검토 | J26: =A23&"|"&C26 -> |P1-4
B27: 교과목 1 | C27: P1-1 | D27: API 설계 문서 | F27: 미제출 | H27: 미검토 | J27: =A27&"|"&C27 -> |P1-1
B28: 교과목 1 | C28: P1-2 | D28: 화면 설계서 | F28: 미제출 | H28: 미검토 | J28: =A27&"|"&C28 -> |P1-2
B29: 교과목 1 | C29: P1-3 | D29: 데이터베이스 설계서 | F29: 미제출 | H29: 미검토 | J29: =A27&"|"&C29 -> |P1-3
B30: 교과목 1 | C30: P1-4 | D30: 대시보드 구현 결과물 | F30: 미제출 | H30: 미검토 | J30: =A27&"|"&C30 -> |P1-4
B31: 교과목 1 | C31: P1-1 | D31: API 설계 문서 | F31: 미제출 | H31: 미검토 | J31: =A31&"|"&C31 -> |P1-1
B32: 교과목 1 | C32: P1-2 | D32: 화면 설계서 | F32: 미제출 | H32: 미검토 | J32: =A31&"|"&C32 -> |P1-2
B33: 교과목 1 | C33: P1-3 | D33: 데이터베이스 설계서 | F33: 미제출 | H33: 미검토 | J33: =A31&"|"&C33 -> |P1-3
B34: 교과목 1 | C34: P1-4 | D34: 대시보드 구현 결과물 | F34: 미제출 | H34: 미검토 | J34: =A31&"|"&C34 -> |P1-4
A35: ■ 교과목 2 | 단일 에이전트 추론 및 AI 오케스트레이션 — 복합 API 연계 일정 조정 에이전트
B36: 교과목 2 | C36: P2-1 | D36: 에이전트 아키텍처 설계서 | F36: 미제출 | H36: 미검토 | J36: =A36&"|"&C36 -> |P2-1
B37: 교과목 2 | C37: P2-2 | D37: 에이전트 시험 결과 보고서 | F37: 미제출 | H37: 미검토 | J37: =A36&"|"&C37 -> |P2-2
B38: 교과목 2 | C38: P2-1 | D38: 에이전트 아키텍처 설계서 | F38: 미제출 | H38: 미검토 | J38: =A38&"|"&C38 -> |P2-1
B39: 교과목 2 | C39: P2-2 | D39: 에이전트 시험 결과 보고서 | F39: 미제출 | H39: 미검토 | J39: =A38&"|"&C39 -> |P2-2
B40: 교과목 2 | C40: P2-1 | D40: 에이전트 아키텍처 설계서 | F40: 미제출 | H40: 미검토 | J40: =A40&"|"&C40 -> |P2-1
...

Sheet 대시보드
A1: 제출 현황 대시보드
A2: [제출현황]을 교과목별로 자동 집계합니다. 이 시트는 직접 수정하지 마세요.
A4: 교과목 1 — AI 서비스 로그 분석 및 운영 대시보드 구축
A5: 팀명 \ 산출물 | B5: P1-1 | C5: P1-2 | D5: P1-3 | E5: P1-4 | F5: 완료 | G5: 완료율
A6: =IF('제출현황'!A3="","",'제출현황'!A3) -> 예시팀명 (팀원 이름) | B6: {=IF('제출현황'!A3="","",IFERROR(INDEX('제출현황'!$F$3:$F$34,MATCH('제출현황'!A3&"|"&"P1-1",'제출현황'!$J$3:$J$34,0)),""))} -> 제출완료 | C6: {=IF('제출현황'!A3="","",IFERROR(INDEX('제출현황'!$F$3:$F$34,MATCH('제출현황'!A3&"|"&"P1-2",'제출현황'!$J$3:$J$34,0)),""))} -> 제출완료 | D6: {=IF('제출현황'!A3="","",IFERROR(INDEX('제출현황'!$F$3:$F$34,MATCH('제출현황'!A3&"|"&"P1-3",'제출현황'!$J$3:$J$34,0)),""))} -> 미제출 | E6: {=IF('제출현황'!A3="","",IFERROR(INDEX('제출현황'!$F$3:$F$34,MATCH('제출현황'!A3&"|"&"P1-4",'제출현황'!$J$3:$J$34,0)),""))} -> 미제출 | F6: =IF('제출현황'!A3="","",COUNTIF('제출현황'!F3:F6,"제출완료")) -> 2 | G6: =IF('제출현황'!A3="","",COUNTIF('제출현황'!F3:F6,"제출완료")/4) -> 0.5
A7: =IF('제출현황'!A7="","",'제출현황'!A7) | B7: {=IF('제출현황'!A7="","",IFERROR(INDEX('제출현황'!$F$3:$F$34,MATCH('제출현황'!A7&"|"&"P1-1",'제출현황'!$J$3:$J$34,0)),""))} | C7: {=IF('제출현황'!A7="","",IFERROR(INDEX('제출현황'!$F$3:$F$34,MATCH('제출현황'!A7&"|"&"P1-2",'제출현황'!$J$3:$J$34,0)),""))} | D7: {=IF('제출현황'!A7="","",IFERROR(INDEX('제출현황'!$F$3:$F$34,MATCH('제출현황'!A7&"|"&"P1-3",'제출현황'!$J$3:$J$34,0)),""))} | E7: {=IF('제출현황'!A7="","",IFERROR(INDEX('제출현황'!$F$3:$F$34,MATCH('제출현황'!A7&"|"&"P1-4",'제출현황'!$J$3:$J$34,0)),""))} | F7: =IF('제출현황'!A7="","",COUNTIF('제출현황'!F7:F10,"제출완료")) | G7: =IF('제출현황'!A7="","",COUNTIF('제출현황'!F7:F10,"제출완료")/4)
A8: =IF('제출현황'!A11="","",'제출현황'!A11) | B8: {=IF('제출현황'!A11="","",IFERROR(INDEX('제출현황'!$F$3:$F$34,MATCH('제출현황'!A11&"|"&"P1-1",'제출현황'!$J$3:$J$34,0)),""))} | C8: {=IF('제출현황'!A11="","",IFERROR(INDEX('제출현황'!$F$3:$F$34,MATCH('제출현황'!A11&"|"&"P1-2",'제출현황'!$J$3:$J$34,0)),""))} | D8: {=IF('제출현황'!A11="","",IFERROR(INDEX('제출현황'!$F$3:$F$34,MATCH('제출현황'!A11&"|"&"P1-3",'제출현황'!$J$3:$J$34,0)),""))} | E8: {=IF('제출현황'!A11="","",IFERROR(INDEX('제출현황'!$F$3:$F$34,MATCH('제출현황'!A11&"|"&"P1-4",'제출현황'!$J$3:$J$34,0)),""))} | F8: =IF('제출현황'!A11="","",COUNTIF('제출현황'!F11:F14,"제출완료")) | G8: =IF('제출현황'!A11="","",COUNTIF('제출현황'!F11:F14,"제출완료")/4)
A9: =IF('제출현황'!A15="","",'제출현황'!A15) | B9: {=IF('제출현황'!A15="","",IFERROR(INDEX('제출현황'!$F$3:$F$34,MATCH('제출현황'!A15&"|"&"P1-1",'제출현황'!$J$3:$J$34,0)),""))} | C9: {=IF('제출현황'!A15="","",IFERROR(INDEX('제출현황'!$F$3:$F$34,MATCH('제출현황'!A15&"|"&"P1-2",'제출현황'!$J$3:$J$34,0)),""))} | D9: {=IF('제출현황'!A15="","",IFERROR(INDEX('제출현황'!$F$3:$F$34,MATCH('제출현황'!A15&"|"&"P1-3",'제출현황'!$J$3:$J$34,0)),""))} | E9: {=IF('제출현황'!A15="","",IFERROR(INDEX('제출현황'!$F$3:$F$34,MATCH('제출현황'!A15&"|"&"P1-4",'제출현황'!$J$3:$J$34,0)),""))} | F9: =IF('제출현황'!A15="","",COUNTIF('제출현황'!F15:F18,"제출완료")) | G9: =IF('제출현황'!A15="","",COUNTIF('제출현황'!F15:F18,"제출완료")/4)
A10: =IF('제출현황'!A19="","",'제출현황'!A19) | B10: {=IF('제출현황'!A19="","",IFERROR(INDEX('제출현황'!$F$3:$F$34,MATCH('제출현황'!A19&"|"&"P1-1",'제출현황'!$J$3:$J$34,0)),""))} | C10: {=IF('제출현황'!A19="","",IFERROR(INDEX('제출현황'!$F$3:$F$34,MATCH('제출현황'!A19&"|"&"P1-2",'제출현황'!$J$3:$J$34,0)),""))} | D10: {=IF('제출현황'!A19="","",IFERROR(INDEX('제출현황'!$F$3:$F$34,MATCH('제출현황'!A19&"|"&"P1-3",'제출현황'!$J$3:$J$34,0)),""))} | E10: {=IF('제출현황'!A19="","",IFERROR(INDEX('제출현황'!$F$3:$F$34,MATCH('제출현황'!A19&"|"&"P1-4",'제출현황'!$J$3:$J$34,0)),""))} | F10: =IF('제출현황'!A19="","",COUNTIF('제출현황'!F19:F22,"제출완료")) | G10: =IF('제출현황'!A19="","",COUNTIF('제출현황'!F19:F22,"제출완료")/4)
A11: =IF('제출현황'!A23="","",'제출현황'!A23) | B11: {=IF('제출현황'!A23="","",IFERROR(INDEX('제출현황'!$F$3:$F$34,MATCH('제출현황'!A23&"|"&"P1-1",'제출현황'!$J$3:$J$34,0)),""))} | C11: {=IF('제출현황'!A23="","",IFERROR(INDEX('제출현황'!$F$3:$F$34,MATCH('제출현황'!A23&"|"&"P1-2",'제출현황'!$J$3:$J$34,0)),""))} | D11: {=IF('제출현황'!A23="","",IFERROR(INDEX('제출현황'!$F$3:$F$34,MATCH('제출현황'!A23&"|"&"P1-3",'제출현황'!$J$3:$J$34,0)),""))} | E11: {=IF('제출현황'!A23="","",IFERROR(INDEX('제출현황'!$F$3:$F$34,MATCH('제출현황'!A23&"|"&"P1-4",'제출현황'!$J$3:$J$34,0)),""))} | F11: =IF('제출현황'!A23="","",COUNTIF('제출현황'!F23:F26,"제출완료")) | G11: =IF('제출현황'!A23="","",COUNTIF('제출현황'!F23:F26,"제출완료")/4)
A12: =IF('제출현황'!A27="","",'제출현황'!A27) | B12: {=IF('제출현황'!A27="","",IFERROR(INDEX('제출현황'!$F$3:$F$34,MATCH('제출현황'!A27&"|"&"P1-1",'제출현황'!$J$3:$J$34,0)),""))} | C12: {=IF('제출현황'!A27="","",IFERROR(INDEX('제출현황'!$F$3:$F$34,MATCH('제출현황'!A27&"|"&"P1-2",'제출현황'!$J$3:$J$34,0)),""))} | D12: {=IF('제출현황'!A27="","",IFERROR(INDEX('제출현황'!$F$3:$F$34,MATCH('제출현황'!A27&"|"&"P1-3",'제출현황'!$J$3:$J$34,0)),""))} | E12: {=IF('제출현황'!A27="","",IFERROR(INDEX('제출현황'!$F$3:$F$34,MATCH('제출현황'!A27&"|"&"P1-4",'제출현황'!$J$3:$J$34,0)),""))} | F12: =IF('제출현황'!A27="","",COUNTIF('제출현황'!F27:F30,"제출완료")) | G12: =IF('제출현황'!A27="","",COUNTIF('제출현황'!F27:F30,"제출완료")/4)
A13: =IF('제출현황'!A31="","",'제출현황'!A31) | B13: {=IF('제출현황'!A31="","",IFERROR(INDEX('제출현황'!$F$3:$F$34,MATCH('제출현황'!A31&"|"&"P1-1",'제출현황'!$J$3:$J$34,0)),""))} | C13: {=IF('제출현황'!A31="","",IFERROR(INDEX('제출현황'!$F$3:$F$34,MATCH('제출현황'!A31&"|"&"P1-2",'제출현황'!$J$3:$J$34,0)),""))} | D13: {=IF('제출현황'!A31="","",IFERROR(INDEX('제출현황'!$F$3:$F$34,MATCH('제출현황'!A31&"|"&"P1-3",'제출현황'!$J$3:$J$34,0)),""))} | E13: {=IF('제출현황'!A31="","",IFERROR(INDEX('제출현황'!$F$3:$F$34,MATCH('제출현황'!A31&"|"&"P1-4",'제출현황'!$J$3:$J$34,0)),""))} | F13: =IF('제출현황'!A31="","",COUNTIF('제출현황'!F31:F34,"제출완료")) | G13: =IF('제출현황'!A31="","",COUNTIF('제출현황'!F31:F34,"제출완료")/4)
A14: 산출물별 완료(건) | B14: =COUNTIFS('제출현황'!$C$3:$C$34,"P1-1",'제출현황'!$F$3:$F$34,"제출완료") -> 1 | C14: =COUNTIFS('제출현황'!$C$3:$C$34,"P1-2",'제출현황'!$F$3:$F$34,"제출완료") -> 1 | D14: =COUNTIFS('제출현황'!$C$3:$C$34,"P1-3",'제출현황'!$F$3:$F$34,"제출완료") -> 0 | E14: =COUNTIFS('제출현황'!$C$3:$C$34,"P1-4",'제출현황'!$F$3:$F$34,"제출완료") -> 0 | F14: =COUNTIF('제출현황'!F3:F34,"제출완료") -> 2
A16: 교과목 2 — 복합 API 연계 일정 조정 에이전트
A17: 팀명 \ 산출물 | B17: P2-1 | C17: P2-2 | D17: 완료 | E17: 완료율
A18: =IF('제출현황'!A36="","",'제출현황'!A36) | B18: {=IF('제출현황'!A36="","",IFERROR(INDEX('제출현황'!$F$36:$F$51,MATCH('제출현황'!A36&"|"&"P2-1",'제출현황'!$J$36:$J$51,0)),""))} | C18: {=IF('제출현황'!A36="","",IFERROR(INDEX('제출현황'!$F$36:$F$51,MATCH('제출현황'!A36&"|"&"P2-2",'제출현황'!$J$36:$J$51,0)),""))} | D18: =IF('제출현황'!A36="","",COUNTIF('제출현황'!F36:F37,"제출완료")) | E18: =IF('제출현황'!A36="","",COUNTIF('제출현황'!F36:F37,"제출완료")/2)
A19: =IF('제출현황'!A38="","",'제출현황'!A38) | B19: {=IF('제출현황'!A38="","",IFERROR(INDEX('제출현황'!$F$36:$F$51,MATCH('제출현황'!A38&"|"&"P2-1",'제출현황'!$J$36:$J$51,0)),""))} | C19: {=IF('제출현황'!A38="","",IFERROR(INDEX('제출현황'!$F$36:$F$51,MATCH('제출현황'!A38&"|"&"P2-2",'제출현황'!$J$36:$J$51,0)),""))} | D19: =IF('제출현황'!A38="","",COUNTIF('제출현황'!F38:F39,"제출완료")) | E19: =IF('제출현황'!A38="","",COUNTIF('제출현황'!F38:F39,"제출완료")/2)
A20: =IF('제출현황'!A40="","",'제출현황'!A40) | B20: {=IF('제출현황'!A40="","",IFERROR(INDEX('제출현황'!$F$36:$F$51,MATCH('제출현황'!A40&"|"&"P2-1",'제출현황'!$J$36:$J$51,0)),""))} | C20: {=IF('제출현황'!A40="","",IFERROR(INDEX('제출현황'!$F$36:$F$51,MATCH('제출현황'!A40&"|"&"P2-2",'제출현황'!$J$36:$J$51,0)),""))} | D20: =IF('제출현황'!A40="","",COUNTIF('제출현황'!F40:F41,"제출완료")) | E20: =IF('제출현황'!A40="","",COUNTIF('제출현황'!F40:F41,"제출완료")/2)
A21: =IF('제출현황'!A42="","",'제출현황'!A42) | B21: {=IF('제출현황'!A42="","",IFERROR(INDEX('제출현황'!$F$36:$F$51,MATCH('제출현황'!A42&"|"&"P2-1",'제출현황'!$J$36:$J$51,0)),""))} | C21: {=IF('제출현황'!A42="","",IFERROR(INDEX('제출현황'!$F$36:$F$51,MATCH('제출현황'!A42&"|"&"P2-2",'제출현황'!$J$36:$J$51,0)),""))} | D21: =IF('제출현황'!A42="","",COUNTIF('제출현황'!F42:F43,"제출완료")) | E21: =IF('제출현황'!A42="","",COUNTIF('제출현황'!F42:F43,"제출완료")/2)
A22: =IF('제출현황'!A44="","",'제출현황'!A44) | B22: {=IF('제출현황'!A44="","",IFERROR(INDEX('제출현황'!$F$36:$F$51,MATCH('제출현황'!A44&"|"&"P2-1",'제출현황'!$J$36:$J$51,0)),""))} | C22: {=IF('제출현황'!A44="","",IFERROR(INDEX('제출현황'!$F$36:$F$51,MATCH('제출현황'!A44&"|"&"P2-2",'제출현황'!$J$36:$J$51,0)),""))} | D22: =IF('제출현황'!A44="","",COUNTIF('제출현황'!F44:F45,"제출완료")) | E22: =IF('제출현황'!A44="","",COUNTIF('제출현황'!F44:F45,"제출완료")/2)
A23: =IF('제출현황'!A46="","",'제출현황'!A46) | B23: {=IF('제출현황'!A46="","",IFERROR(INDEX('제출현황'!$F$36:$F$51,MATCH('제출현황'!A46&"|"&"P2-1",'제출현황'!$J$36:$J$51,0)),""))} | C23: {=IF('제출현황'!A46="","",IFERROR(INDEX('제출현황'!$F$36:$F$51,MATCH('제출현황'!A46&"|"&"P2-2",'제출현황'!$J$36:$J$51,0)),""))} | D23: =IF('제출현황'!A46="","",COUNTIF('제출현황'!F46:F47,"제출완료")) | E23: =IF('제출현황'!A46="","",COUNTIF('제출현황'!F46:F47,"제출완료")/2)
A24: =IF('제출현황'!A48="","",'제출현황'!A48) | B24: {=IF('제출현황'!A48="","",IFERROR(INDEX('제출현황'!$F$36:$F$51,MATCH('제출현황'!A48&"|"&"P2-1",'제출현황'!$J$36:$J$51,0)),""))} | C24: {=IF('제출현황'!A48="","",IFERROR(INDEX('제출현황'!$F$36:$F$51,MATCH('제출현황'!A48&"|"&"P2-2",'제출현황'!$J$36:$J$51,0)),""))} | D24: =IF('제출현황'!A48="","",COUNTIF('제출현황'!F48:F49,"제출완료")) | E24: =IF('제출현황'!A48="","",COUNTIF('제출현황'!F48:F49,"제출완료")/2)
A25: =IF('제출현황'!A50="","",'제출현황'!A50) | B25: {=IF('제출현황'!A50="","",IFERROR(INDEX('제출현황'!$F$36:$F$51,MATCH('제출현황'!A50&"|"&"P2-1",'제출현황'!$J$36:$J$51,0)),""))} | C25: {=IF('제출현황'!A50="","",IFERROR(INDEX('제출현황'!$F$36:$F$51,MATCH('제출현황'!A50&"|"&"P2-2",'제출현황'!$J$36:$J$51,0)),""))} | D25: =IF('제출현황'!A50="","",COUNTIF('제출현황'!F50:F51,"제출완료")) | E25: =IF('제출현황'!A50="","",COUNTIF('제출현황'!F50:F51,"제출완료")/2)
A26: 산출물별 완료(건) | B26: =COUNTIFS('제출현황'!$C$36:$C$51,"P2-1",'제출현황'!$F$36:$F$51,"제출완료") -> 0 | C26: =COUNTIFS('제출현황'!$C$36:$C$51,"P2-2",'제출현황'!$F$36:$F$51,"제출완료") -> 0 | D26: =COUNTIF('제출현황'!F36:F51,"제출완료") -> 0
A28: 교과목 3 — 에러 자가 치유(Auto Healing) 워크플로우
A29: 팀명 \ 산출물 | B29: P3-1 | C29: P3-2 | D29: P3-3 | E29: 완료 | F29: 완료율
A30: =IF('제출현황'!A53="","",'제출현황'!A53) | B30: {=IF('제출현황'!A53="","",IFERROR(INDEX('제출현황'!$F$53:$F$76,MATCH('제출현황'!A53&"|"&"P3-1",'제출현황'!$J$53:$J$76,0)),""))} | C30: {=IF('제출현황'!A53="","",IFERROR(INDEX('제출현황'!$F$53:$F$76,MATCH('제출현황'!A53&"|"&"P3-2",'제출현황'!$J$53:$J$76,0)),""))} | D30: {=IF('제출현황'!A53="","",IFERROR(INDEX('제출현황'!$F$53:$F$76,MATCH('제출현황'!A53&"|"&"P3-3",'제출현황'!$J$53:$J$76,0)),""))} | E30: =IF('제출현황'!A53="","",COUNTIF('제출현황'!F53:F55,"제출완료")) | F30: =IF('제출현황'!A53="","",COUNTIF('제출현황'!F53:F55,"제출완료")/3)
A31: =IF('제출현황'!A56="","",'제출현황'!A56) | B31: {=IF('제출현황'!A56="","",IFERROR(INDEX('제출현황'!$F$53:$F$76,MATCH('제출현황'!A56&"|"&"P3-1",'제출현황'!$J$53:$J$76,0)),""))} | C31: {=IF('제출현황'!A56="","",IFERROR(INDEX('제출현황'!$F$53:$F$76,MATCH('제출현황'!A56&"|"&"P3-2",'제출현황'!$J$53:$J$76,0)),""))} | D31: {=IF('제출현황'!A56="","",IFERROR(INDEX('제출현황'!$F$53:$F$76,MATCH('제출현황'!A56&"|"&"P3-3",'제출현황'!$J$53:$J$76,0)),""))} | E31: =IF('제출현황'!A56="","",COUNTIF('제출현황'!F56:F58,"제출완료")) | F31: =IF('제출현황'!A56="","",COUNTIF('제출현황'!F56:F58,"제출완료")/3)
A32: =IF('제출현황'!A59="","",'제출현황'!A59) | B32: {=IF('제출현황'!A59="","",IFERROR(INDEX('제출현황'!$F$53:$F$76,MATCH('제출현황'!A59&"|"&"P3-1",'제출현황'!$J$53:$J$76,0)),""))} | C32: {=IF('제출현황'!A59="","",IFERROR(INDEX('제출현황'!$F$53:$F$76,MATCH('제출현황'!A59&"|"&"P3-2",'제출현황'!$J$53:$J$76,0)),""))} | D32: {=IF('제출현황'!A59="","",IFERROR(INDEX('제출현황'!$F$53:$F$76,MATCH('제출현황'!A59&"|"&"P3-3",'제출현황'!$J$53:$J$76,0)),""))} | E32: =IF('제출현황'!A59="","",COUNTIF('제출현황'!F59:F61,"제출완료")) | F32: =IF('제출현황'!A59="","",COUNTIF('제출현황'!F59:F61,"제출완료")/3)
A33: =IF('제출현황'!A62="","",'제출현황'!A62) | B33: {=IF('제출현황'!A62="","",IFERROR(INDEX('제출현황'!$F$53:$F$76,MATCH('제출현황'!A62&"|"&"P3-1",'제출현황'!$J$53:$J$76,0)),""))} | C33: {=IF('제출현황'!A62="","",IFERROR(INDEX('제출현황'!$F$53:$F$76,MATCH('제출현황'!A62&"|"&"P3-2",'제출현황'!$J$53:$J$76,0)),""))} | D33: {=IF('제출현황'!A62="","",IFERROR(INDEX('제출현황'!$F$53:$F$76,MATCH('제출현황'!A62&"|"&"P3-3",'제출현황'!$J$53:$J$76,0)),""))} | E33: =IF('제출현황'!A62="","",COUNTIF('제출현황'!F62:F64,"제출완료")) | F33: =IF('제출현황'!A62="","",COUNTIF('제출현황'!F62:F64,"제출완료")/3)
A34: =IF('제출현황'!A65="","",'제출현황'!A65) | B34: {=IF('제출현황'!A65="","",IFERROR(INDEX('제출현황'!$F$53:$F$76,MATCH('제출현황'!A65&"|"&"P3-1",'제출현황'!$J$53:$J$76,0)),""))} | C34: {=IF('제출현황'!A65="","",IFERROR(INDEX('제출현황'!$F$53:$F$76,MATCH('제출현황'!A65&"|"&"P3-2",'제출현황'!$J$53:$J$76,0)),""))} | D34: {=IF('제출현황'!A65="","",IFERROR(INDEX('제출현황'!$F$53:$F$76,MATCH('제출현황'!A65&"|"&"P3-3",'제출현황'!$J$53:$J$76,0)),""))} | E34: =IF('제출현황'!A65="","",COUNTIF('제출현황'!F65:F67,"제출완료")) | F34: =IF('제출현황'!A65="","",COUNTIF('제출현황'!F65:F67,"제출완료")/3)
A35: =IF('제출현황'!A68="","",'제출현황'!A68) | B35: {=IF('제출현황'!A68="","",IFERROR(INDEX('제출현황'!$F$53:$F$76,MATCH('제출현황'!A68&"|"&"P3-1",'제출현황'!$J$53:$J$76,0)),""))} | C35: {=IF('제출현황'!A68="","",IFERROR(INDEX('제출현황'!$F$53:$F$76,MATCH('제출현황'!A68&"|"&"P3-2",'제출현황'!$J$53:$J$76,0)),""))} | D35: {=IF('제출현황'!A68="","",IFERROR(INDEX('제출현황'!$F$53:$F$76,MATCH('제출현황'!A68&"|"&"P3-3",'제출현황'!$J$53:$J$76,0)),""))} | E35: =IF('제출현황'!A68="","",COUNTIF('제출현황'!F68:F70,"제출완료")) | F35: =IF('제출현황'!A68="","",COUNTIF('제출현황'!F68:F70,"제출완료")/3)
A36: =IF('제출현황'!A71="","",'제출현황'!A71) | B36: {=IF('제출현황'!A71="","",IFERROR(INDEX('제출현황'!$F$53:$F$76,MATCH('제출현황'!A71&"|"&"P3-1",'제출현황'!$J$53:$J$76,0)),""))} | C36: {=IF('제출현황'!A71="","",IFERROR(INDEX('제출현황'!$F$53:$F$76,MATCH('제출현황'!A71&"|"&"P3-2",'제출현황'!$J$53:$J$76,0)),""))} | D36: {=IF('제출현황'!A71="","",IFERROR(INDEX('제출현황'!$F$53:$F$76,MATCH('제출현황'!A71&"|"&"P3-3",'제출현황'!$J$53:$J$76,0)),""))} | E36: =IF('제출현황'!A71="","",COUNTIF('제출현황'!F71:F73,"제출완료")) | F36: =IF('제출현황'!A71="","",COUNTIF('제출현황'!F71:F73,"제출완료")/3)
A37: =IF('제출현황'!A74="","",'제출현황'!A74) | B37: {=IF('제출현황'!A74="","",IFERROR(INDEX('제출현황'!$F$53:$F$76,MATCH('제출현황'!A74&"|"&"P3-1",'제출현황'!$J$53:$J$76,0)),""))} | C37: {=IF('제출현황'!A74="","",IFERROR(INDEX('제출현황'!$F$53:$F$76,MATCH('제출현황'!A74&"|"&"P3-2",'제출현황'!$J$53:$J$76,0)),""))} | D37: {=IF('제출현황'!A74="","",IFERROR(INDEX('제출현황'!$F$53:$F$76,MATCH('제출현황'!A74&"|"&"P3-3",'제출현황'!$J$53:$J$76,0)),""))} | E37: =IF('제출현황'!A74="","",COUNTIF('제출현황'!F74:F76,"제출완료")) | F37: =IF('제출현황'!A74="","",COUNTIF('제출현황'!F74:F76,"제출완료")/3)
A38: 산출물별 완료(건) | B38: =COUNTIFS('제출현황'!$C$53:$C$76,"P3-1",'제출현황'!$F$53:$F$76,"제출완료") -> 0 | C38: =COUNTIFS('제출현황'!$C$53:$C$76,"P3-2",'제출현황'!$F$53:$F$76,"제출완료") -> 0 | D38: =COUNTIFS('제출현황'!$C$53:$C$76,"P3-3",'제출현황'!$F$53:$F$76,"제출완료") -> 0 | E38: =COUNTIF('제출현황'!F53:F76,"제출완료") -> 0
A40: 교과목 4 — 노코드·로코드 기반 기업형 지능형 기술 지원 자동화(Tech Support) 워크플로우
A41: 팀명 \ 산출물 | B41: P4-1 | C41: P4-2 | D41: P4-3 | E41: 완료 | F41: 완료율
A42: =IF('제출현황'!A78="","",'제출현황'!A78) | B42: {=IF('제출현황'!A78="","",IFERROR(INDEX('제출현황'!$F$78:$F$101,MATCH('제출현황'!A78&"|"&"P4-1",'제출현황'!$J$78:$J$101,0)),""))} | C42: {=IF('제출현황'!A78="","",IFERROR(INDEX('제출현황'!$F$78:$F$101,MATCH('제출현황'!A78&"|"&"P4-2",'제출현황'!$J$78:$J$101,0)),""))} | D42: {=IF('제출현황'!A78="","",IFERROR(INDEX('제출현황'!$F$78:$F$101,MATCH('제출현황'!A78&"|"&"P4-3",'제출현황'!$J$78:$J$101,0)),""))} | E42: =IF('제출현황'!A78="","",COUNTIF('제출현황'!F78:F80,"제출완료")) | F42: =IF('제출현황'!A78="","",COUNTIF('제출현황'!F78:F80,"제출완료")/3)
A43: =IF('제출현황'!A81="","",'제출현황'!A81) | B43: {=IF('제출현황'!A81="","",IFERROR(INDEX('제출현황'!$F$78:$F$101,MATCH('제출현황'!A81&"|"&"P4-1",'제출현황'!$J$78:$J$101,0)),""))} | C43: {=IF('제출현황'!A81="","",IFERROR(INDEX('제출현황'!$F$78:$F$101,MATCH('제출현황'!A81&"|"&"P4-2",'제출현황'!$J$78:$J$101,0)),""))} | D43: {=IF('제출현황'!A81="","",IFERROR(INDEX('제출현황'!$F$78:$F$101,MATCH('제출현황'!A81&"|"&"P4-3",'제출현황'!$J$78:$J$101,0)),""))} | E43: =IF('제출현황'!A81="","",COUNTIF('제출현황'!F81:F83,"제출완료")) | F43: =IF('제출현황'!A81="","",COUNTIF('제출현황'!F81:F83,"제출완료")/3)
A44: =IF('제출현황'!A84="","",'제출현황'!A84) | B44: {=IF('제출현황'!A84="","",IFERROR(INDEX('제출현황'!$F$78:$F$101,MATCH('제출현황'!A84&"|"&"P4-1",'제출현황'!$J$78:$J$101,0)),""))} | C44: {=IF('제출현황'!A84="","",IFERROR(INDEX('제출현황'!$F$78:$F$101,MATCH('제출현황'!A84&"|"&"P4-2",'제출현황'!$J$78:$J$101,0)),""))} | D44: {=IF('제출현황'!A84="","",IFERROR(INDEX('제출현황'!$F$78:$F$101,MATCH('제출현황'!A84&"|"&"P4-3",'제출현황'!$J$78:$J$101,0)),""))} | E44: =IF('제출현황'!A84="","",COUNTIF('제출현황'!F84:F86,"제출완료")) | F44: =IF('제출현황'!A84="","",COUNTIF('제출현황'!F84:F86,"제출완료")/3)
...
